Workbook

Sheet Guide
A1: School Management System
A2: Start here. Work through the tabs from left to right.
A5: TAB MAP
A6: Tab | B6: What it is for | C6: You type here?
A7: Dashboard | B7: Live totals per school, with charts | C7: No, automatic
A8: Report Card | B8: Printable report card for one student | C8: Only the Student ID
A9: Results | B9: Ranked results for a whole class and term, printable | C9: School, class and term
A10: Class List | B10: Register of up to 40 students per class, printable | C10: School and class
A11: ID Cards | B11: Printable student ID cards for a class | C11: School and class
A12: Timetable View | B12: Weekly timetable for a class, printable | C12: School and class
A13: Settings | B13: Academic year, currency, classes, subjects, grade bands | C13: Yes, once
A14: Schools | B14: One row per school | C14: Yes
A15: Classes | B15: Classes in each school and their class teacher | C15: Yes
A16: Teachers | B16: Staff list | C16: Yes
A17: Students | B17: Student list (the master list) | C17: Yes
... A24: Email Log | B24: Record of every registration email sent | C24: No, automatic
A26: SET UP (ONCE)
A27: 1. Settings: enter the academic year, currency, your classes, subjects and grade bands.
A28: 2. Schools: add each school. IDs (SCH01, SCH02...) appear automatically.
A29: 3. Teachers, then Classes, then Students: add people. IDs (T001, S0001...) appear automatically. Pick School ID and Class from the dropdowns.
A31: EVERY DAY / EVERY TERM
A32: Daily: Attendance. Pick the Student ID and mark P, A or L.
A33: Each term: Grades (scores per subject) and Fees (amount due and paid).
A34: Reports: open Report Card, pick a Student ID, then print.
A36: REGISTRATION EMAILS (GOOGLE SHEETS ONLY)
A37: When you register a school, teacher or student (name, school, class and email filled in), a welcome email is sent automatically. Students' emails go to the guardian.
A38: 1. Upload this file to Google Drive, open it, then File > Save as Google Sheets.
A39: 2. In the Google Sheet: Extensions > Apps Script. Delete any code, paste the contents of Code.gs, click Save.
... A76: Set up the buttons once: Extensions > Apps Script > add a new file, paste EmailReports.gs, Save. Reload the sheet, then Email Reports > Run setup and approve the permissions. If you use Lock formulas and set roles, unlock the yellow input cells on Class Attendance and Class Grades for teachers.

Sheet Dashboard
A1: School Dashboard
A2: =" Academic year "&Settings!B5&" | Currency: "&Settings!B6&" | Emails sent: "&COUNTIF('Email Log'!$G$5:$G$304,"Sent*")&" | Updates automatically" -> Academic year 2026/2027 | Currency: SLE | Emails sent: 0 | Updates automatically
A5: TOTAL STUDENTS | C5: TOTAL TEACHERS | F5: ATTENDANCE RATE | I5: FEES COLLECTED
A6: =SUM(Schools!$G$5:$G$304) -> 1 | C6: =SUM(Schools!$H$5:$H$304) -> 1 | F6: =IF(COUNTA(Attendance!$F$5:$F$304)=0,"-",(COUNTIF(Attendance!$F$5:$F$304,"P")+COUNTIF(Attendance!$F$5:$F$304,"L"))/COUNTA(Attendance!$F$5:$F$304)) -> 1 | I6: =IF(SUM(Fees!$F$5:$F$304)=0,"-",SUM(Fees!$G$5:$G$304)/SUM(Fees!$F$5:$F$304)) -> 0.6
A8: BY SCHOOL
A9: School ID | B9: School Name | C9: Students | D9: Teachers | E9: Student : Teacher | F9: Attendance Rate | G9: Avg Score | H9: Fees Due | I9: Fees Paid | J9: Fees Balance | K9: Collection Rate
A10: =IF(Schools!A5="","",Schools!A5) -> SCH01 | B10: =IF($A10="","",Schools!B5) -> Example Primary School | C10: =IF($A10="","",Schools!G5) -> 1 | D10: =IF($A10="","",Schools!H5) -> 1 | E10: =IF($A10="","",IF(D10=0,"-",ROUND(C10/D10,1))) -> 1 | F10: =IF($A10="","",IF(COUNTIF(Attendance!$D$5:$D$304,$A10)=0,"-",(COUNTIFS(Attendance!$D$5:$D$304,$A10,Attendance!$F$5:$F$304,"P")+COUNTIFS(Attendance!$D$5:$D$304,$A10,Attendance!$F$5:$F$304,"L"))/COUNTIF(Attendance!$D$5:$D$304,$A10))) -> 1 | G10: =IF($A10="","",IFERROR(AVERAGEIF(Grades!$C$5:$C$304,$A10,Grades!$I$5:$I$304),"-")) -> 77.7 | H10: =IF($A10="","",SUMIF(Fees!$C$5:$C$304,$A10,Fees!$F$5:$F$304)) -> 500 | I10: =IF($A10="","",SUMIF(Fees!$C$5:$C$304,$A10,Fees!$G$5:$G$304)) -> 300 | J10: =IF($A10="","",H10-I10) -> 200 | K10: =IF($A10="","",IF(H10=0,"-",I10/H10)) -> 0.6
A11: =IF(Schools!A6="","",Schools!A6) | B11: =IF($A11="","",Schools!B6) | C11: =IF($A11="","",Schools!G6) | D11: =IF($A11="","",Schools!H6) | E11: =IF($A11="","",IF(D11=0,"-",ROUND(C11/D11,1))) | F11: =IF($A11="","",IF(COUNTIF(Attendance!$D$5:$D$304,$A11)=0,"-",(COUNTIFS(Attendance!$D$5:$D$304,$A11,Attendance!$F$5:$F$304,"P")+COUNTIFS(Attendance!$D$5:$D$304,$A11,Attendance!$F$5:$F$304,"L"))/COUNTIF(Attendance!$D$5:$D$304,$A11))) | G11: =IF($A11="","",IFERROR(AVERAGEIF(Grades!$C$5:$C$304,$A11,Grades!$I$5:$I$304),"-")) | H11: =IF($A11="","",SUMIF(Fees!$C$5:$C$304,$A11,Fees!$F$5:$F$304)) | I11: =IF($A11="","",SUMIF(Fees!$C$5:$C$304,$A11,Fees!$G$5:$G$304)) | J11: =IF($A11="","",H11-I11) | K11: =IF($A11="","",IF(H11=0,"-",I11/H11))
A12: =IF(Schools!A7="","",Schools!A7) | B12: =IF($A12="","",Schools!B7) | C12: =IF($A12="","",Schools!G7) | D12: =IF($A12="","",Schools!H7) | E12: =IF($A12="","",IF(D12=0,"-",ROUND(C12/D12,1))) | F12: =IF($A12="","",IF(COUNTIF(Attendance!$D$5:$D$304,$A12)=0,"-",(COUNTIFS(Attendance!$D$5:$D$304,$A12,Attendance!$F$5:$F$304,"P")+COUNTIFS(Attendance!$D$5:$D$304,$A12,Attendance!$F$5:$F$304,"L"))/COUNTIF(Attendance!$D$5:$D$304,$A12))) | G12: =IF($A12="","",IFERROR(AVERAGEIF(Grades!$C$5:$C$304,$A12,Grades!$I$5:$I$304),"-")) | H12: =IF($A12="","",SUMIF(Fees!$C$5:$C$304,$A12,Fees!$F$5:$F$304)) | I12: =IF($A12="","",SUMIF(Fees!$C$5:$C$304,$A12,Fees!$G$5:$G$304)) | J12: =IF($A12="","",H12-I12) | K12: =IF($A12="","",IF(H12=0,"-",I12/H12))
A13: =IF(Schools!A8="","",Schools!A8) | B13: =IF($A13="","",Schools!B8) | C13: =IF($A13="","",Schools!G8) | D13: =IF($A13="","",Schools!H8) | E13: =IF($A13="","",IF(D13=0,"-",ROUND(C13/D13,1))) | F13: =IF($A13="","",IF(COUNTIF(Attendance!$D$5:$D$304,$A13)=0,"-",(COUNTIFS(Attendance!$D$5:$D$304,$A13,Attendance!$F$5:$F$304,"P")+COUNTIFS(Attendance!$D$5:$D$304,$A13,Attendance!$F$5:$F$304,"L"))/COUNTIF(Attendance!$D$5:$D$304,$A13))) | G13: =IF($A13="","",IFERROR(AVERAGEIF(Grades!$C$5:$C$304,$A13,Grades!$I$5:$I$304),"-")) | H13: =IF($A13="","",SUMIF(Fees!$C$5:$C$304,$A13,Fees!$F$5:$F$304)) | I13: =IF($A13="","",SUMIF(Fees!$C$5:$C$304,$A13,Fees!$G$5:$G$304)) | J13: =IF($A13="","",H13-I13) | K13: =IF($A13="","",IF(H13=0,"-",I13/H13))
A14: =IF(Schools!A9="","",Schools!A9) | B14: =IF($A14="","",Schools!B9) | C14: =IF($A14="","",Schools!G9) | D14: =IF($A14="","",Schools!H9) | E14: =IF($A14="","",IF(D14=0,"-",ROUND(C14/D14,1))) | F14: =IF($A14="","",IF(COUNTIF(Attendance!$D$5:$D$304,$A14)=0,"-",(COUNTIFS(Attendance!$D$5:$D$304,$A14,Attendance!$F$5:$F$304,"P")+COUNTIFS(Attendance!$D$5:$D$304,$A14,Attendance!$F$5:$F$304,"L"))/COUNTIF(Attendance!$D$5:$D$304,$A14))) | G14: =IF($A14="","",IFERROR(AVERAGEIF(Grades!$C$5:$C$304,$A14,Grades!$I$5:$I$304),"-")) | H14: =IF($A14="","",SUMIF(Fees!$C$5:$C$304,$A14,Fees!$F$5:$F$304)) | I14: =IF($A14="","",SUMIF(Fees!$C$5:$C$304,$A14,Fees!$G$5:$G$304)) | J14: =IF($A14="","",H14-I14) | K14: =IF($A14="","",IF(H14=0,"-",I14/H14))
A15: =IF(Schools!A10="","",Schools!A10) | B15: =IF($A15="","",Schools!B10) | C15: =IF($A15="","",Schools!G10) | D15: =IF($A15="","",Schools!H10) | E15: =IF($A15="","",IF(D15=0,"-",ROUND(C15/D15,1))) | F15: =IF($A15="","",IF(COUNTIF(Attendance!$D$5:$D$304,$A15)=0,"-",(COUNTIFS(Attendance!$D$5:$D$304,$A15,Attendance!$F$5:$F$304,"P")+COUNTIFS(Attendance!$D$5:$D$304,$A15,Attendance!$F$5:$F$304,"L"))/COUNTIF(Attendance!$D$5:$D$304,$A15))) | G15: =IF($A15="","",IFERROR(AVERAGEIF(Grades!$C$5:$C$304,$A15,Grades!$I$5:$I$304),"-")) | H15: =IF($A15="","",SUMIF(Fees!$C$5:$C$304,$A15,Fees!$F$5:$F$304)) | I15: =IF($A15="","",SUMIF(Fees!$C$5:$C$304,$A15,Fees!$G$5:$G$304)) | J15: =IF($A15="","",H15-I15) | K15: =IF($A15="","",IF(H15=0,"-",I15/H15))
A16: =IF(Schools!A11="","",Schools!A11) | B16: =IF($A16="","",Schools!B11) | C16: =IF($A16="","",Schools!G11) | D16: =IF($A16="","",Schools!H11) | E16: =IF($A16="","",IF(D16=0,"-",ROUND(C16/D16,1))) | F16: =IF($A16="","",IF(COUNTIF(Attendance!$D$5:$D$304,$A16)=0,"-",(COUNTIFS(Attendance!$D$5:$D$304,$A16,Attendance!$F$5:$F$304,"P")+COUNTIFS(Attendance!$D$5:$D$304,$A16,Attendance!$F$5:$F$304,"L"))/COUNTIF(Attendance!$D$5:$D$304,$A16))) | G16: =IF($A16="","",IFERROR(AVERAGEIF(Grades!$C$5:$C$304,$A16,Grades!$I$5:$I$304),"-")) | H16: =IF($A16="","",SUMIF(Fees!$C$5:$C$304,$A16,Fees!$F$5:$F$304)) | I16: =IF($A16="","",SUMIF(Fees!$C$5:$C$304,$A16,Fees!$G$5:$G$304)) | J16: =IF($A16="","",H16-I16) | K16: =IF($A16="","",IF(H16=0,"-",I16/H16))
A17: =IF(Schools!A12="","",Schools!A12) | B17: =IF($A17="","",Schools!B12) | C17: =IF($A17="","",Schools!G12) | D17: =IF($A17="","",Schools!H12) | E17: =IF($A17="","",IF(D17=0,"-",ROUND(C17/D17,1))) | F17: =IF($A17="","",IF(COUNTIF(Attendance!$D$5:$D$304,$A17)=0,"-",(COUNTIFS(Attendance!$D$5:$D$304,$A17,Attendance!$F$5:$F$304,"P")+COUNTIFS(Attendance!$D$5:$D$304,$A17,Attendance!$F$5:$F$304,"L"))/COUNTIF(Attendance!$D$5:$D$304,$A17))) | G17: =IF($A17="","",IFERROR(AVERAGEIF(Grades!$C$5:$C$304,$A17,Grades!$I$5:$I$304),"-")) | H17: =IF($A17="","",SUMIF(Fees!$C$5:$C$304,$A17,Fees!$F$5:$F$304)) | I17: =IF($A17="","",SUMIF(Fees!$C$5:$C$304,$A17,Fees!$G$5:$G$304)) | J17: =IF($A17="","",H17-I17) | K17: =IF($A17="","",IF(H17=0,"-",I17/H17))
A18: =IF(Schools!A13="","",Schools!A13) | B18: =IF($A18="","",Schools!B13) | C18: =IF($A18="","",Schools!G13) | D18: =IF($A18="","",Schools!H13) | E18: =IF($A18="","",IF(D18=0,"-",ROUND(C18/D18,1))) | F18: =IF($A18="","",IF(COUNTIF(Attendance!$D$5:$D$304,$A18)=0,"-",(COUNTIFS(Attendance!$D$5:$D$304,$A18,Attendance!$F$5:$F$304,"P")+COUNTIFS(Attendance!$D$5:$D$304,$A18,Attendance!$F$5:$F$304,"L"))/COUNTIF(Attendance!$D$5:$D$304,$A18))) | G18: =IF($A18="","",IFERROR(AVERAGEIF(Grades!$C$5:$C$304,$A18,Grades!$I$5:$I$304),"-")) | H18: =IF($A18="","",SUMIF(Fees!$C$5:$C$304,$A18,Fees!$F$5:$F$304)) | I18: =IF($A18="","",SUMIF(Fees!$C$5:$C$304,$A18,Fees!$G$5:$G$304)) | J18: =IF($A18="","",H18-I18) | K18: =IF($A18="","",IF(H18=0,"-",I18/H18))
A19: =IF(Schools!A14="","",Schools!A14) | B19: =IF($A19="","",Schools!B14) | C19: =IF($A19="","",Schools!G14) | D19: =IF($A19="","",Schools!H14) | E19: =IF($A19="","",IF(D19=0,"-",ROUND(C19/D19,1))) | F19: =IF($A19="","",IF(COUNTIF(Attendance!$D$5:$D$304,$A19)=0,"-",(COUNTIFS(Attendance!$D$5:$D$304,$A19,Attendance!$F$5:$F$304,"P")+COUNTIFS(Attendance!$D$5:$D$304,$A19,Attendance!$F$5:$F$304,"L"))/COUNTIF(Attendance!$D$5:$D$304,$A19))) | G19: =IF($A19="","",IFERROR(AVERAGEIF(Grades!$C$5:$C$304,$A19,Grades!$I$5:$I$304),"-")) | H19: =IF($A19="","",SUMIF(Fees!$C$5:$C$304,$A19,Fees!$F$5:$F$304)) | I19: =IF($A19="","",SUMIF(Fees!$C$5:$C$304,$A19,Fees!$G$5:$G$304)) | J19: =IF($A19="","",H19-I19) | K19: =IF($A19="","",IF(H19=0,"-",I19/H19))
A20: =IF(Schools!A15="","",Schools!A15) | B20: =IF($A20="","",Schools!B15) | C20: =IF($A20="","",Schools!G15) | D20: =IF($A20="","",Schools!H15) | E20: =IF($A20="","",IF(D20=0,"-",ROUND(C20/D20,1))) | F20: =IF($A20="","",IF(COUNTIF(Attendance!$D$5:$D$304,$A20)=0,"-",(COUNTIFS(Attendance!$D$5:$D$304,$A20,Attendance!$F$5:$F$304,"P")+COUNTIFS(Attendance!$D$5:$D$304,$A20,Attendance!$F$5:$F$304,"L"))/COUNTIF(Attendance!$D$5:$D$304,$A20))) | G20: =IF($A20="","",IFERROR(AVERAGEIF(Grades!$C$5:$C$304,$A20,Grades!$I$5:$I$304),"-")) | H20: =IF($A20="","",SUMIF(Fees!$C$5:$C$304,$A20,Fees!$F$5:$F$304)) | I20: =IF($A20="","",SUMIF(Fees!$C$5:$C$304,$A20,Fees!$G$5:$G$304)) | J20: =IF($A20="","",H20-I20) | K20: =IF($A20="","",IF(H20=0,"-",I20/H20))
A21: =IF(Schools!A16="","",Schools!A16) | B21: =IF($A21="","",Schools!B16) | C21: =IF($A21="","",Schools!G16) | D21: =IF($A21="","",Schools!H16) | E21: =IF($A21="","",IF(D21=0,"-",ROUND(C21/D21,1))) | F21: =IF($A21="","",IF(COUNTIF(Attendance!$D$5:$D$304,$A21)=0,"-",(COUNTIFS(Attendance!$D$5:$D$304,$A21,Attendance!$F$5:$F$304,"P")+COUNTIFS(Attendance!$D$5:$D$304,$A21,Attendance!$F$5:$F$304,"L"))/COUNTIF(Attendance!$D$5:$D$304,$A21))) | G21: =IF($A21="","",IFERROR(AVERAGEIF(Grades!$C$5:$C$304,$A21,Grades!$I$5:$I$304),"-")) | H21: =IF($A21="","",SUMIF(Fees!$C$5:$C$304,$A21,Fees!$F$5:$F$304)) | I21: =IF($A21="","",SUMIF(Fees!$C$5:$C$304,$A21,Fees!$G$5:$G$304)) | J21: =IF($A21="","",H21-I21) | K21: =IF($A21="","",IF(H21=0,"-",I21/H21))
... A24: =IF(Schools!A19="","",Schools!A19) | B24: =IF($A24="","",Schools!B19) | C24: =IF($A24="","",Schools!G19) | D24: =IF($A24="","",Schools!H19) | E24: =IF($A24="","",IF(D24=0,"-",ROUND(C24/D24,1))) | F24: =IF($A24="","",IF(COUNTIF(Attendance!$D$5:$D$304,$A24)=0,"-",(COUNTIFS(Attendance!$D$5:$D$304,$A24,Attendance!$F$5:$F$304,"P")+COUNTIFS(Attendance!$D$5:$D$304,$A24,Attendance!$F$5:$F$304,"L"))/COUNTIF(Attendance!$D$5:$D$304,$A24))) | G24: =IF($A24="","",IFERROR(AVERAGEIF(Grades!$C$5:$C$304,$A24,Grades!$I$5:$I$304),"-")) | H24: =IF($A24="","",SUMIF(Fees!$C$5:$C$304,$A24,Fees!$F$5:$F$304)) | I24: =IF($A24="","",SUMIF(Fees!$C$5:$C$304,$A24,Fees!$G$5:$G$304)) | J24: =IF($A24="","",H24-I24) | K24: =IF($A24="","",IF(H24=0,"-",I24/H24))
A25: Red attendance = below 85%, green = 95%+. Red collection = below 60%, green = 90%+. Attendance counts Present and Late as attended.
A26: CHARTS (first 8 schools)

Sheet Report Card
A1: Student Report Card
A2: Pick a Student ID and a Term in the yellow cells. Everything else fills in. Print or email this page for the parent.
I4: Print button (set up via School System menu)
A5: STUDENT ID | B5: S0001 | E5: OVERALL AVERAGE | G5: =IF($E$30="","",$E$30) -> 77.7 | K5: Term start (auto) | L5: =IF(OR($B$10="",$B$10="All terms"),0,IFERROR(IF(INDEX(Settings!$B$36:$B$38,MATCH($B$10,Settings!$A$36:$A$38,0))="",0,INDEX(Settings!$B$36:$B$38,MATCH($B$10,Settings!$A$36:$A$38,0))),0)) -> 0
A6: NAME | B6: =IF($B$5="","",IFERROR(INDEX(Students!$B$5:$B$304,MATCH($B$5,Students!$A$5:$A$304,0)),"ID not found")) -> Aminata Conteh | E6: OVERALL GRADE | G6: =IF($E$30="","",IF($E$30>=Settings!$E$11,Settings!$F$11,IF($E$30>=Settings!$E$12,Settings!$F$12,IF($E$30>=Settings!$E$13,Settings!$F$13,IF($E$30>=Settings!$E$14,Settings!$F$14,Settings!$F$15))))) -> B | I6: EMAIL REPORT CARD | K6: Term end (auto) | L6: =IF(OR($B$10="",$B$10="All terms"),99999,IFERROR(IF(INDEX(Settings!$C$36:$C$38,MATCH($B$10,Settings!$A$36:$A$38,0))="",99999,INDEX(Settings!$C$36:$C$38,MATCH($B$10,Settings!$A$36:$A$38,0))),99999)) -> 99999
A7: CLASS | B7: =IF($B$5="","",IFERROR(INDEX(Students!$F$5:$F$304,MATCH($B$5,Students!$A$5:$A$304,0)),"")) -> Class 4 | E7: ATTENDANCE RATE | G7: =IF($B$5="","",IF(COUNTIFS(Attendance!$B$5:$B$304,$B$5,Attendance!$A$5:$A$304,">="&$L$5,Attendance!$A$5:$A$304,"<="&$L$6)=0,"-",(COUNTIFS(Attendance!$B$5:$B$304,$B$5,Attendance!$A$5:$A$304,">="&$L$5,Attendance!$A$5:$A$304,"<="&$L$6,Attendance!$F$5:$F$304,"P")+COUNTIFS(Attendance!$B$5:$B$304,$B$5,Attendance!$A$5:$A$304,">="&$L$5,Attendance!$A$5:$A$304,"<="&$L$6,Attendance!$F$5:$F$304,"L"))/COUNTIFS(Attendance!$B$5:$B$304,$B$5,Attendance!$A$5:$A$304,">="&$L$5,Attendance!$A$5:$A$304,"<="&$L$6))) -> 1 | I7: SAVE PDF TO DRIVE
A8: SCHOOL | B8: =IF($B$5="","",IFERROR(INDEX(Schools!$B$5:$B$304,MATCH(INDEX(Students!$E$5:$E$304,MATCH($B$5,Students!$A$5:$A$304,0)),Schools!$A$5:$A$304,0)),"")) -> Example Primary School | E8: PRESENT / ABSENT / LATE | G8: =IF($B$5="","",COUNTIFS(Attendance!$B$5:$B$304,$B$5,Attendance!$A$5:$A$304,">="&$L$5,Attendance!$A$5:$A$304,"<="&$L$6,Attendance!$F$5:$F$304,"P")&" / "&COUNTIFS(Attendance!$B$5:$B$304,$B$5,Attendance!$A$5:$A$304,">="&$L$5,Attendance!$A$5:$A$304,"<="&$L$6,Attendance!$F$5:$F$304,"A")&" / "&COUNTIFS(Attendance!$B$5:$B$304,$B$5,Attendance!$A$5:$A$304,">="&$L$5,Attendance!$A$5:$A$304,"<="&$L$6,Attendance!$F$5:$F$304,"L")) -> 1 / 0 / 0 | I8: Buttons: School System > Email Reports > Run setup
A9: ACADEMIC YEAR | B9: =Settings!B5 -> 2026/2027 | E9: FEES BALANCE | G9: =IF($B$5="","",IF(OR($B$10="",$B$10="All terms"),SUMIF(Fees!$A$5:$A$304,$B$5,Fees!$I$5:$I$304),SUMIFS(Fees!$I$5:$I$304,Fees!$A$5:$A$304,$B$5,Fees!$E$5:$E$304,$B$10))) -> 200
A10: REPORT TERM | B10: Term 1 | E10: GUARDIAN EMAIL | G10: =IF($B$5="","",IFERROR(IF(INDEX(Students!$L$5:$L$304,MATCH($B$5,Students!$A$5:$A$304,0))="","no email on file",INDEX(Students!$L$5:$L$304,MATCH($B$5,Students!$A$5:$A$304,0))),"")) -> no email on file
A12: Subject | B12: =Settings!A11 -> Term 1 | C12: =Settings!A12 -> Term 2 | D12: =Settings!A13 -> Term 3 | E12: =IF(OR($B$10="",$B$10="All terms"),"Average","Term score") -> Term score | F12: Grade | G12: Remark
A13: =IF(Settings!C11="","",Settings!C11) -> English Language | B13: =IF(OR($A13="",AND($B$10<>"",$B$10<>"All terms",$B$10<>B$12)),"",IFERROR(AVERAGEIFS(Grades!$I$5:$I$304,Grades!$A$5:$A$304,$B$5,Grades!$E$5:$E$304,$A13,Grades!$F$5:$F$304,B$12),"")) | C13: =IF(OR($A13="",AND($B$10<>"",$B$10<>"All terms",$B$10<>C$12)),"",IFERROR(AVERAGEIFS(Grades!$I$5:$I$304,Grades!$A$5:$A$304,$B$5,Grades!$E$5:$E$304,$A13,Grades!$F$5:$F$304,C$12),"")) | D13: =IF(OR($A13="",AND($B$10<>"",$B$10<>"All terms",$B$10<>D$12)),"",IFERROR(AVERAGEIFS(Grades!$I$5:$I$304,Grades!$A$5:$A$304,$B$5,Grades!$E$5:$E$304,$A13,Grades!$F$5:$F$304,D$12),"")) | E13: =IF(COUNT(B13:D13)=0,"",AVERAGE(B13:D13)) | F13: =IF(E13="","",IF(E13>=Settings!$E$11,Settings!$F$11,IF(E13>=Settings!$E$12,Settings!$F$12,IF(E13>=Settings!$E$13,Settings!$F$13,IF(E13>=Settings!$E$14,Settings!$F$14,Settings!$F$15))))) | G13: =IF(E13="","",IF(E13>=Settings!$E$11,Settings!$G$11,IF(E13>=Settings!$E$12,Settings!$G$12,IF(E13>=Settings!$E$13,Settings!$G$13,IF(E13>=Settings!$E$14,Settings!$G$14,Settings!$G$15)))))
A14: =IF(Settings!C12="","",Settings!C12) -> Mathematics | B14: =IF(OR($A14="",AND($B$10<>"",$B$10<>"All terms",$B$10<>B$12)),"",IFERROR(AVERAGEIFS(Grades!$I$5:$I$304,Grades!$A$5:$A$304,$B$5,Grades!$E$5:$E$304,$A14,Grades!$F$5:$F$304,B$12),"")) -> 77.7 | C14: =IF(OR($A14="",AND($B$10<>"",$B$10<>"All terms",$B$10<>C$12)),"",IFERROR(AVERAGEIFS(Grades!$I$5:$I$304,Grades!$A$5:$A$304,$B$5,Grades!$E$5:$E$304,$A14,Grades!$F$5:$F$304,C$12),"")) | D14: =IF(OR($A14="",AND($B$10<>"",$B$10<>"All terms",$B$10<>D$12)),"",IFERROR(AVERAGEIFS(Grades!$I$5:$I$304,Grades!$A$5:$A$304,$B$5,Grades!$E$5:$E$304,$A14,Grades!$F$5:$F$304,D$12),"")) | E14: =IF(COUNT(B14:D14)=0,"",AVERAGE(B14:D14)) -> 77.7 | F14: =IF(E14="","",IF(E14>=Settings!$E$11,Settings!$F$11,IF(E14>=Settings!$E$12,Settings!$F$12,IF(E14>=Settings!$E$13,Settings!$F$13,IF(E14>=Settings!$E$14,Settings!$F$14,Settings!$F$15))))) -> B | G14: =IF(E14="","",IF(E14>=Settings!$E$11,Settings!$G$11,IF(E14>=Settings!$E$12,Settings!$G$12,IF(E14>=Settings!$E$13,Settings!$G$13,IF(E14>=Settings!$E$14,Settings!$G$14,Settings!$G$15))))) -> Very Good
A15: =IF(Settings!C13="","",Settings!C13) -> Integrated Science | B15: =IF(OR($A15="",AND($B$10<>"",$B$10<>"All terms",$B$10<>B$12)),"",IFERROR(AVERAGEIFS(Grades!$I$5:$I$304,Grades!$A$5:$A$304,$B$5,Grades!$E$5:$E$304,$A15,Grades!$F$5:$F$304,B$12),"")) | C15: =IF(OR($A15="",AND($B$10<>"",$B$10<>"All terms",$B$10<>C$12)),"",IFERROR(AVERAGEIFS(Grades!$I$5:$I$304,Grades!$A$5:$A$304,$B$5,Grades!$E$5:$E$304,$A15,Grades!$F$5:$F$304,C$12),"")) | D15: =IF(OR($A15="",AND($B$10<>"",$B$10<>"All terms",$B$10<>D$12)),"",IFERROR(AVERAGEIFS(Grades!$I$5:$I$304,Grades!$A$5:$A$304,$B$5,Grades!$E$5:$E$304,$A15,Grades!$F$5:$F$304,D$12),"")) | E15: =IF(COUNT(B15:D15)=0,"",AVERAGE(B15:D15)) | F15: =IF(E15="","",IF(E15>=Settings!$E$11,Settings!$F$11,IF(E15>=Settings!$E$12,Settings!$F$12,IF(E15>=Settings!$E$13,Settings!$F$13,IF(E15>=Settings!$E$14,Settings!$F$14,Settings!$F$15))))) | G15: =IF(E15="","",IF(E15>=Settings!$E$11,Settings!$G$11,IF(E15>=Settings!$E$12,Settings!$G$12,IF(E15>=Settings!$E$13,Settings!$G$13,IF(E15>=Settings!$E$14,Settings!$G$14,Settings!$G$15)))))
A16: =IF(Settings!C14="","",Settings!C14) -> Social Studies | B16: =IF(OR($A16="",AND($B$10<>"",$B$10<>"All terms",$B$10<>B$12)),"",IFERROR(AVERAGEIFS(Grades!$I$5:$I$304,Grades!$A$5:$A$304,$B$5,Grades!$E$5:$E$304,$A16,Grades!$F$5:$F$304,B$12),"")) | C16: =IF(OR($A16="",AND($B$10<>"",$B$10<>"All terms",$B$10<>C$12)),"",IFERROR(AVERAGEIFS(Grades!$I$5:$I$304,Grades!$A$5:$A$304,$B$5,Grades!$E$5:$E$304,$A16,Grades!$F$5:$F$304,C$12),"")) | D16: =IF(OR($A16="",AND($B$10<>"",$B$10<>"All terms",$B$10<>D$12)),"",IFERROR(AVERAGEIFS(Grades!$I$5:$I$304,Grades!$A$5:$A$304,$B$5,Grades!$E$5:$E$304,$A16,Grades!$F$5:$F$304,D$12),"")) | E16: =IF(COUNT(B16:D16)=0,"",AVERAGE(B16:D16)) | F16: =IF(E16="","",IF(E16>=Settings!$E$11,Settings!$F$11,IF(E16>=Settings!$E$12,Settings!$F$12,IF(E16>=Settings!$E$13,Settings!$F$13,IF(E16>=Settings!$E$14,Settings!$F$14,Settings!$F$15))))) | G16: =IF(E16="","",IF(E16>=Settings!$E$11,Settings!$G$11,IF(E16>=Settings!$E$12,Settings!$G$12,IF(E16>=Settings!$E$13,Settings!$G$13,IF(E16>=Settings!$E$14,Settings!$G$14,Settings!$G$15)))))
A17: =IF(Settings!C15="","",Settings!C15) -> Religious & Moral Education | B17: =IF(OR($A17="",AND($B$10<>"",$B$10<>"All terms",$B$10<>B$12)),"",IFERROR(AVERAGEIFS(Grades!$I$5:$I$304,Grades!$A$5:$A$304,$B$5,Grades!$E$5:$E$304,$A17,Grades!$F$5:$F$304,B$12),"")) | C17: =IF(OR($A17="",AND($B$10<>"",$B$10<>"All terms",$B$10<>C$12)),"",IFERROR(AVERAGEIFS(Grades!$I$5:$I$304,Grades!$A$5:$A$304,$B$5,Grades!$E$5:$E$304,$A17,Grades!$F$5:$F$304,C$12),"")) | D17: =IF(OR($A17="",AND($B$10<>"",$B$10<>"All terms",$B$10<>D$12)),"",IFERROR(AVERAGEIFS(Grades!$I$5:$I$304,Grades!$A$5:$A$304,$B$5,Grades!$E$5:$E$304,$A17,Grades!$F$5:$F$304,D$12),"")) | E17: =IF(COUNT(B17:D17)=0,"",AVERAGE(B17:D17)) | F17: =IF(E17="","",IF(E17>=Settings!$E$11,Settings!$F$11,IF(E17>=Settings!$E$12,Settings!$F$12,IF(E17>=Settings!$E$13,Settings!$F$13,IF(E17>=Settings!$E$14,Settings!$F$14,Settings!$F$15))))) | G17: =IF(E17="","",IF(E17>=Settings!$E$11,Settings!$G$11,IF(E17>=Settings!$E$12,Settings!$G$12,IF(E17>=Settings!$E$13,Settings!$G$13,IF(E17>=Settings!$E$14,Settings!$G$14,Settings!$G$15)))))
A18: =IF(Settings!C16="","",Settings!C16) -> Physical Education | B18: =IF(OR($A18="",AND($B$10<>"",$B$10<>"All terms",$B$10<>B$12)),"",IFERROR(AVERAGEIFS(Grades!$I$5:$I$304,Grades!$A$5:$A$304,$B$5,Grades!$E$5:$E$304,$A18,Grades!$F$5:$F$304,B$12),"")) | C18: =IF(OR($A18="",AND($B$10<>"",$B$10<>"All terms",$B$10<>C$12)),"",IFERROR(AVERAGEIFS(Grades!$I$5:$I$304,Grades!$A$5:$A$304,$B$5,Grades!$E$5:$E$304,$A18,Grades!$F$5:$F$304,C$12),"")) | D18: =IF(OR($A18="",AND($B$10<>"",$B$10<>"All terms",$B$10<>D$12)),"",IFERROR(AVERAGEIFS(Grades!$I$5:$I$304,Grades!$A$5:$A$304,$B$5,Grades!$E$5:$E$304,$A18,Grades!$F$5:$F$304,D$12),"")) | E18: =IF(COUNT(B18:D18)=0,"",AVERAGE(B18:D18)) | F18: =IF(E18="","",IF(E18>=Settings!$E$11,Settings!$F$11,IF(E18>=Settings!$E$12,Settings!$F$12,IF(E18>=Settings!$E$13,Settings!$F$13,IF(E18>=Settings!$E$14,Settings!$F$14,Settings!$F$15))))) | G18: =IF(E18="","",IF(E18>=Settings!$E$11,Settings!$G$11,IF(E18>=Settings!$E$12,Settings!$G$12,IF(E18>=Settings!$E$13,Settings!$G$13,IF(E18>=Settings!$E$14,Settings!$G$14,Settings!$G$15)))))
A19: =IF(Settings!C17="","",Settings!C17) -> Creative Arts | B19: =IF(OR($A19="",AND($B$10<>"",$B$10<>"All terms",$B$10<>B$12)),"",IFERROR(AVERAGEIFS(Grades!$I$5:$I$304,Grades!$A$5:$A$304,$B$5,Grades!$E$5:$E$304,$A19,Grades!$F$5:$F$304,B$12),"")) | C19: =IF(OR($A19="",AND($B$10<>"",$B$10<>"All terms",$B$10<>C$12)),"",IFERROR(AVERAGEIFS(Grades!$I$5:$I$304,Grades!$A$5:$A$304,$B$5,Grades!$E$5:$E$304,$A19,Grades!$F$5:$F$304,C$12),"")) | D19: =IF(OR($A19="",AND($B$10<>"",$B$10<>"All terms",$B$10<>D$12)),"",IFERROR(AVERAGEIFS(Grades!$I$5:$I$304,Grades!$A$5:$A$304,$B$5,Grades!$E$5:$E$304,$A19,Grades!$F$5:$F$304,D$12),"")) | E19: =IF(COUNT(B19:D19)=0,"",AVERAGE(B19:D19)) | F19: =IF(E19="","",IF(E19>=Settings!$E$11,Settings!$F$11,IF(E19>=Settings!$E$12,Settings!$F$12,IF(E19>=Settings!$E$13,Settings!$F$13,IF(E19>=Settings!$E$14,Settings!$F$14,Settings!$F$15))))) | G19: =IF(E19="","",IF(E19>=Settings!$E$11,Settings!$G$11,IF(E19>=Settings!$E$12,Settings!$G$12,IF(E19>=Settings!$E$13,Settings!$G$13,IF(E19>=Settings!$E$14,Settings!$G$14,Settings!$G$15)))))
A20: =IF(Settings!C18="","",Settings!C18) -> Computer Studies | B20: =IF(OR($A20="",AND($B$10<>"",$B$10<>"All terms",$B$10<>B$12)),"",IFERROR(AVERAGEIFS(Grades!$I$5:$I$304,Grades!$A$5:$A$304,$B$5,Grades!$E$5:$E$304,$A20,Grades!$F$5:$F$304,B$12),"")) | C20: =IF(OR($A20="",AND($B$10<>"",$B$10<>"All terms",$B$10<>C$12)),"",IFERROR(AVERAGEIFS(Grades!$I$5:$I$304,Grades!$A$5:$A$304,$B$5,Grades!$E$5:$E$304,$A20,Grades!$F$5:$F$304,C$12),"")) | D20: =IF(OR($A20="",AND($B$10<>"",$B$10<>"All terms",$B$10<>D$12)),"",IFERROR(AVERAGEIFS(Grades!$I$5:$I$304,Grades!$A$5:$A$304,$B$5,Grades!$E$5:$E$304,$A20,Grades!$F$5:$F$304,D$12),"")) | E20: =IF(COUNT(B20:D20)=0,"",AVERAGE(B20:D20)) | F20: =IF(E20="","",IF(E20>=Settings!$E$11,Settings!$F$11,IF(E20>=Settings!$E$12,Settings!$F$12,IF(E20>=Settings!$E$13,Settings!$F$13,IF(E20>=Settings!$E$14,Settings!$F$14,Settings!$F$15))))) | G20: =IF(E20="","",IF(E20>=Settings!$E$11,Settings!$G$11,IF(E20>=Settings!$E$12,Settings!$G$12,IF(E20>=Settings!$E$13,Settings!$G$13,IF(E20>=Settings!$E$14,Settings!$G$14,Settings!$G$15)))))
A21: =IF(Settings!C19="","",Settings!C19) -> French | B21: =IF(OR($A21="",AND($B$10<>"",$B$10<>"All terms",$B$10<>B$12)),"",IFERROR(AVERAGEIFS(Grades!$I$5:$I$304,Grades!$A$5:$A$304,$B$5,Grades!$E$5:$E$304,$A21,Grades!$F$5:$F$304,B$12),"")) | C21: =IF(OR($A21="",AND($B$10<>"",$B$10<>"All terms",$B$10<>C$12)),"",IFERROR(AVERAGEIFS(Grades!$I$5:$I$304,Grades!$A$5:$A$304,$B$5,Grades!$E$5:$E$304,$A21,Grades!$F$5:$F$304,C$12),"")) | D21: =IF(OR($A21="",AND($B$10<>"",$B$10<>"All terms",$B$10<>D$12)),"",IFERROR(AVERAGEIFS(Grades!$I$5:$I$304,Grades!$A$5:$A$304,$B$5,Grades!$E$5:$E$304,$A21,Grades!$F$5:$F$304,D$12),"")) | E21: =IF(COUNT(B21:D21)=0,"",AVERAGE(B21:D21)) | F21: =IF(E21="","",IF(E21>=Settings!$E$11,Settings!$F$11,IF(E21>=Settings!$E$12,Settings!$F$12,IF(E21>=Settings!$E$13,Settings!$F$13,IF(E21>=Settings!$E$14,Settings!$F$14,Settings!$F$15))))) | G21: =IF(E21="","",IF(E21>=Settings!$E$11,Settings!$G$11,IF(E21>=Settings!$E$12,Settings!$G$12,IF(E21>=Settings!$E$13,Settings!$G$13,IF(E21>=Settings!$E$14,Settings!$G$14,Settings!$G$15)))))
A22: =IF(Settings!C20="","",Settings!C20) -> Agriculture | B22: =IF(OR($A22="",AND($B$10<>"",$B$10<>"All terms",$B$10<>B$12)),"",IFERROR(AVERAGEIFS(Grades!$I$5:$I$304,Grades!$A$5:$A$304,$B$5,Grades!$E$5:$E$304,$A22,Grades!$F$5:$F$304,B$12),"")) | C22: =IF(OR($A22="",AND($B$10<>"",$B$10<>"All terms",$B$10<>C$12)),"",IFERROR(AVERAGEIFS(Grades!$I$5:$I$304,Grades!$A$5:$A$304,$B$5,Grades!$E$5:$E$304,$A22,Grades!$F$5:$F$304,C$12),"")) | D22: =IF(OR($A22="",AND($B$10<>"",$B$10<>"All terms",$B$10<>D$12)),"",IFERROR(AVERAGEIFS(Grades!$I$5:$I$304,Grades!$A$5:$A$304,$B$5,Grades!$E$5:$E$304,$A22,Grades!$F$5:$F$304,D$12),"")) | E22: =IF(COUNT(B22:D22)=0,"",AVERAGE(B22:D22)) | F22: =IF(E22="","",IF(E22>=Settings!$E$11,Settings!$F$11,IF(E22>=Settings!$E$12,Settings!$F$12,IF(E22>=Settings!$E$13,Settings!$F$13,IF(E22>=Settings!$E$14,Settings!$F$14,Settings!$F$15))))) | G22: =IF(E22="","",IF(E22>=Settings!$E$11,Settings!$G$11,IF(E22>=Settings!$E$12,Settings!$G$12,IF(E22>=Settings!$E$13,Settings!$G$13,IF(E22>=Settings!$E$14,Settings!$G$14,Settings!$G$15)))))
A23: =IF(Settings!C21="","",Settings!C21) | B23: =IF(OR($A23="",AND($B$10<>"",$B$10<>"All terms",$B$10<>B$12)),"",IFERROR(AVERAGEIFS(Grades!$I$5:$I$304,Grades!$A$5:$A$304,$B$5,Grades!$E$5:$E$304,$A23,Grades!$F$5:$F$304,B$12),"")) | C23: =IF(OR($A23="",AND($B$10<>"",$B$10<>"All terms",$B$10<>C$12)),"",IFERROR(AVERAGEIFS(Grades!$I$5:$I$304,Grades!$A$5:$A$304,$B$5,Grades!$E$5:$E$304,$A23,Grades!$F$5:$F$304,C$12),"")) | D23: =IF(OR($A23="",AND($B$10<>"",$B$10<>"All terms",$B$10<>D$12)),"",IFERROR(AVERAGEIFS(Grades!$I$5:$I$304,Grades!$A$5:$A$304,$B$5,Grades!$E$5:$E$304,$A23,Grades!$F$5:$F$304,D$12),"")) | E23: =IF(COUNT(B23:D23)=0,"",AVERAGE(B23:D23)) | F23: =IF(E23="","",IF(E23>=Settings!$E$11,Settings!$F$11,IF(E23>=Settings!$E$12,Settings!$F$12,IF(E23>=Settings!$E$13,Settings!$F$13,IF(E23>=Settings!$E$14,Settings!$F$14,Settings!$F$15))))) | G23: =IF(E23="","",IF(E23>=Settings!$E$11,Settings!$G$11,IF(E23>=Settings!$E$12,Settings!$G$12,IF(E23>=Settings!$E$13,Settings!$G$13,IF(E23>=Settings!$E$14,Settings!$G$14,Settings!$G$15)))))
A24: =IF(Settings!C22="","",Settings!C22) | B24: =IF(OR($A24="",AND($B$10<>"",$B$10<>"All terms",$B$10<>B$12)),"",IFERROR(AVERAGEIFS(Grades!$I$5:$I$304,Grades!$A$5:$A$304,$B$5,Grades!$E$5:$E$304,$A24,Grades!$F$5:$F$304,B$12),"")) | C24: =IF(OR($A24="",AND($B$10<>"",$B$10<>"All terms",$B$10<>C$12)),"",IFERROR(AVERAGEIFS(Grades!$I$5:$I$304,Grades!$A$5:$A$304,$B$5,Grades!$E$5:$E$304,$A24,Grades!$F$5:$F$304,C$12),"")) | D24: =IF(OR($A24="",AND($B$10<>"",$B$10<>"All terms",$B$10<>D$12)),"",IFERROR(AVERAGEIFS(Grades!$I$5:$I$304,Grades!$A$5:$A$304,$B$5,Grades!$E$5:$E$304,$A24,Grades!$F$5:$F$304,D$12),"")) | E24: =IF(COUNT(B24:D24)=0,"",AVERAGE(B24:D24)) | F24: =IF(E24="","",IF(E24>=Settings!$E$11,Settings!$F$11,IF(E24>=Settings!$E$12,Settings!$F$12,IF(E24>=Settings!$E$13,Settings!$F$13,IF(E24>=Settings!$E$14,Settings!$F$14,Settings!$F$15))))) | G24: =IF(E24="","",IF(E24>=Settings!$E$11,Settings!$G$11,IF(E24>=Settings!$E$12,Settings!$G$12,IF(E24>=Settings!$E$13,Settings!$G$13,IF(E24>=Settings!$E$14,Settings!$G$14,Settings!$G$15)))))
... A27: =IF(Settings!C25="","",Settings!C25) | B27: =IF(OR($A27="",AND($B$10<>"",$B$10<>"All terms",$B$10<>B$12)),"",IFERROR(AVERAGEIFS(Grades!$I$5:$I$304,Grades!$A$5:$A$304,$B$5,Grades!$E$5:$E$304,$A27,Grades!$F$5:$F$304,B$12),"")) | C27: =IF(OR($A27="",AND($B$10<>"",$B$10<>"All terms",$B$10<>C$12)),"",IFERROR(AVERAGEIFS(Grades!$I$5:$I$304,Grades!$A$5:$A$304,$B$5,Grades!$E$5:$E$304,$A27,Grades!$F$5:$F$304,C$12),"")) | D27: =IF(OR($A27="",AND($B$10<>"",$B$10<>"All terms",$B$10<>D$12)),"",IFERROR(AVERAGEIFS(Grades!$I$5:$I$304,Grades!$A$5:$A$304,$B$5,Grades!$E$5:$E$304,$A27,Grades!$F$5:$F$304,D$12),"")) | E27: =IF(COUNT(B27:D27)=0,"",AVERAGE(B27:D27)) | F27: =IF(E27="","",IF(E27>=Settings!$E$11,Settings!$F$11,IF(E27>=Settings!$E$12,Settings!$F$12,IF(E27>=Settings!$E$13,Settings!$F$13,IF(E27>=Settings!$E$14,Settings!$F$14,Settings!$F$15))))) | G27: =IF(E27="","",IF(E27>=Settings!$E$11,Settings!$G$11,IF(E27>=Settings!$E$12,Settings!$G$12,IF(E27>=Settings!$E$13,Settings!$G$13,IF(E27>=Settings!$E$14,Settings!$G$14,Settings!$G$15)))))
A30: Overall average | B30: =IF(COUNT(B13:B27)=0,"",AVERAGE(B13:B27)) -> 77.7 | C30: =IF(COUNT(C13:C27)=0,"",AVERAGE(C13:C27)) | D30: =IF(COUNT(D13:D27)=0,"",AVERAGE(D13:D27)) | E30: =IF(COUNT(E13:E27)=0,"",AVERAGE(E13:E27)) -> 77.7 | F30: =IF(E30="","",IF(E30>=Settings!$E$11,Settings!$F$11,IF(E30>=Settings!$E$12,Settings!$F$12,IF(E30>=Settings!$E$13,Settings!$F$13,IF(E30>=Settings!$E$14,Settings!$F$14,Settings!$F$15))))) -> B | G30: =IF(E30="","",IF(E30>=Settings!$E$11,Settings!$G$11,IF(E30>=Settings!$E$12,Settings!$G$12,IF(E30>=Settings!$E$13,Settings!$G$13,IF(E30>=Settings!$E$14,Settings!$G$14,Settings!$G$15))))) -> Very Good
A33: Class teacher: ____________________________ | E33: Date: ____________
A35: Head teacher: ____________________________ | E35: Date: ____________
A37: Parent / guardian: ____________________________ | E37: Date: ____________

Sheet Results
A1: Class Results
A2: Pick a School ID, Class and Term. Students are listed, ranked by average, ready to print.
A4: SCHOOL ID | C4: SCH01 | D4: =IF($C$4="","",IFERROR(INDEX(Schools!$B$5:$B$304,MATCH($C$4,Schools!$A$5:$A$304,0)),"School not found")) -> Example Primary School | U4: EMAIL REPORT CARDS (THIS CLASS & TERM)
A5: CLASS | C5: Class 4 | D5: =IF($C$5="","",COUNTIFS(Students!$E$5:$E$304,$C$4,Students!$F$5:$F$304,$C$5,Students!$K$5:$K$304,"Active")&" active students | "&$C$6&" | "&Settings!B5) -> 1 active students | Term 1 | 2026/2027 | U5: EMAIL RESULTS TO CLASS TEACHER
A6: TERM | C6: Term 1 | U6: Buttons: School System > Email Reports > Run setup
A7: Shows the first 12 subjects in Settings. Position is by average score; equal averages share a position. Each student has a separate report card per term: use Email Report Cards for this class and term.
A9: No. | B9: Student ID | C9: Student Name | D9: =IF(Settings!C11="","",Settings!C11) -> English Language | E9: =IF(Settings!C12="","",Settings!C12) -> Mathematics | F9: =IF(Settings!C13="","",Settings!C13) -> Integrated Science | G9: =IF(Settings!C14="","",Settings!C14) -> Social Studies | H9: =IF(Settings!C15="","",Settings!C15) -> Religious & Moral Education | I9: =IF(Settings!C16="","",Settings!C16) -> Physical Education | J9: =IF(Settings!C17="","",Settings!C17) -> Creative Arts | K9: =IF(Settings!C18="","",Settings!C18) -> Computer Studies | L9: =IF(Settings!C19="","",Settings!C19) -> French | M9: =IF(Settings!C20="","",Settings!C20) -> Agriculture | N9: =IF(Settings!C21="","",Settings!C21) | O9: =IF(Settings!C22="","",Settings!C22) | P9: Total | Q9: Average | R9: Grade | S9: Position
A10: =IF($B10="","",1) -> 1 | B10: =IFERROR(INDEX(Students!$A$5:$A$304,MATCH($C$4&"|"&$C$5&"|"&1,Students!$O$5:$O$304,0)),"") -> S0001 | C10: =IF($B10="","",INDEX(Students!$B$5:$B$304,MATCH($B10,Students!$A$5:$A$304,0))) -> Aminata Conteh | D10: =IF(OR($B10="",D$9=""),"",IFERROR(AVERAGEIFS(Grades!$I$5:$I$304,Grades!$A$5:$A$304,$B10,Grades!$E$5:$E$304,D$9,Grades!$F$5:$F$304,$C$6),"")) | E10: =IF(OR($B10="",E$9=""),"",IFERROR(AVERAGEIFS(Grades!$I$5:$I$304,Grades!$A$5:$A$304,$B10,Grades!$E$5:$E$304,E$9,Grades!$F$5:$F$304,$C$6),"")) -> 77.7 | F10: =IF(OR($B10="",F$9=""),"",IFERROR(AVERAGEIFS(Grades!$I$5:$I$304,Grades!$A$5:$A$304,$B10,Grades!$E$5:$E$304,F$9,Grades!$F$5:$F$304,$C$6),"")) | G10: =IF(OR($B10="",G$9=""),"",IFERROR(AVERAGEIFS(Grades!$I$5:$I$304,Grades!$A$5:$A$304,$B10,Grades!$E$5:$E$304,G$9,Grades!$F$5:$F$304,$C$6),"")) | H10: =IF(OR($B10="",H$9=""),"",IFERROR(AVERAGEIFS(Grades!$I$5:$I$304,Grades!$A$5:$A$304,$B10,Grades!$E$5:$E$304,H$9,Grades!$F$5:$F$304,$C$6),"")) | I10: =IF(OR($B10="",I$9=""),"",IFERROR(AVERAGEIFS(Grades!$I$5:$I$304,Grades!$A$5:$A$304,$B10,Grades!$E$5:$E$304,I$9,Grades!$F$5:$F$304,$C$6),"")) | J10: =IF(OR($B10="",J$9=""),"",IFERROR(AVERAGEIFS(Grades!$I$5:$I$304,Grades!$A$5:$A$304,$B10,Grades!$E$5:$E$304,J$9,Grades!$F$5:$F$304,$C$6),"")) | K10: =IF(OR($B10="",K$9=""),"",IFERROR(AVERAGEIFS(Grades!$I$5:$I$304,Grades!$A$5:$A$304,$B10,Grades!$E$5:$E$304,K$9,Grades!$F$5:$F$304,$C$6),"")) | ... O10: =IF(OR($B10="",O$9=""),"",IFERROR(AVERAGEIFS(Grades!$I$5:$I$304,Grades!$A$5:$A$304,$B10,Grades!$E$5:$E$304,O$9,Grades!$F$5:$F$304,$C$6),"")) | P10: =IF(COUNT(D10:O10)=0,"",SUM(D10:O10)) -> 77.7 | Q10: =IF(COUNT(D10:O10)=0,"",AVERAGE(D10:O10)) -> 77.7 | R10: =IF(Q10="","",IF(Q10>=Settings!$E$11,Settings!$F$11,IF(Q10>=Settings!$E$12,Settings!$F$12,IF(Q10>=Settings!$E$13,Settings!$F$13,IF(Q10>=Settings!$E$14,Settings!$F$14,Settings!$F$15))))) -> B | S10: =IF(Q10="","",RANK(Q10,$Q$10:$Q$49)) -> 1
A11: =IF($B11="","",2) | B11: =IFERROR(INDEX(Students!$A$5:$A$304,MATCH($C$4&"|"&$C$5&"|"&2,Students!$O$5:$O$304,0)),"") | C11: =IF($B11="","",INDEX(Students!$B$5:$B$304,MATCH($B11,Students!$A$5:$A$304,0))) | D11: =IF(OR($B11="",D$9=""),"",IFERROR(AVERAGEIFS(Grades!$I$5:$I$304,Grades!$A$5:$A$304,$B11,Grades!$E$5:$E$304,D$9,Grades!$F$5:$F$304,$C$6),"")) | E11: =IF(OR($B11="",E$9=""),"",IFERROR(AVERAGEIFS(Grades!$I$5:$I$304,Grades!$A$5:$A$304,$B11,Grades!$E$5:$E$304,E$9,Grades!$F$5:$F$304,$C$6),"")) | F11: =IF(OR($B11="",F$9=""),"",IFERROR(AVERAGEIFS(Grades!$I$5:$I$304,Grades!$A$5:$A$304,$B11,Grades!$E$5:$E$304,F$9,Grades!$F$5:$F$304,$C$6),"")) | G11: =IF(OR($B11="",G$9=""),"",IFERROR(AVERAGEIFS(Grades!$I$5:$I$304,Grades!$A$5:$A$304,$B11,Grades!$E$5:$E$304,G$9,Grades!$F$5:$F$304,$C$6),"")) | H11: =IF(OR($B11="",H$9=""),"",IFERROR(AVERAGEIFS(Grades!$I$5:$I$304,Grades!$A$5:$A$304,$B11,Grades!$E$5:$E$304,H$9,Grades!$F$5:$F$304,$C$6),"")) | I11: =IF(OR($B11="",I$9=""),"",IFERROR(AVERAGEIFS(Grades!$I$5:$I$304,Grades!$A$5:$A$304,$B11,Grades!$E$5:$E$304,I$9,Grades!$F$5:$F$304,$C$6),"")) | J11: =IF(OR($B11="",J$9=""),"",IFERROR(AVERAGEIFS(Grades!$I$5:$I$304,Grades!$A$5:$A$304,$B11,Grades!$E$5:$E$304,J$9,Grades!$F$5:$F$304,$C$6),"")) | K11: =IF(OR($B11="",K$9=""),"",IFERROR(AVERAGEIFS(Grades!$I$5:$I$304,Grades!$A$5:$A$304,$B11,Grades!$E$5:$E$304,K$9,Grades!$F$5:$F$304,$C$6),"")) | ... O11: =IF(OR($B11="",O$9=""),"",IFERROR(AVERAGEIFS(Grades!$I$5:$I$304,Grades!$A$5:$A$304,$B11,Grades!$E$5:$E$304,O$9,Grades!$F$5:$F$304,$C$6),"")) | P11: =IF(COUNT(D11:O11)=0,"",SUM(D11:O11)) | Q11: =IF(COUNT(D11:O11)=0,"",AVERAGE(D11:O11)) | R11: =IF(Q11="","",IF(Q11>=Settings!$E$11,Settings!$F$11,IF(Q11>=Settings!$E$12,Settings!$F$12,IF(Q11>=Settings!$E$13,Settings!$F$13,IF(Q11>=Settings!$E$14,Settings!$F$14,Settings!$F$15))))) | S11: =IF(Q11="","",RANK(Q11,$Q$10:$Q$49))
A12: =IF($B12="","",3) | B12: =IFERROR(INDEX(Students!$A$5:$A$304,MATCH($C$4&"|"&$C$5&"|"&3,Students!$O$5:$O$304,0)),"") | C12: =IF($B12="","",INDEX(Students!$B$5:$B$304,MATCH($B12,Students!$A$5:$A$304,0))) | D12: =IF(OR($B12="",D$9=""),"",IFERROR(AVERAGEIFS(Grades!$I$5:$I$304,Grades!$A$5:$A$304,$B12,Grades!$E$5:$E$304,D$9,Grades!$F$5:$F$304,$C$6),"")) | E12: =IF(OR($B12="",E$9=""),"",IFERROR(AVERAGEIFS(Grades!$I$5:$I$304,Grades!$A$5:$A$304,$B12,Grades!$E$5:$E$304,E$9,Grades!$F$5:$F$304,$C$6),"")) | F12: =IF(OR($B12="",F$9=""),"",IFERROR(AVERAGEIFS(Grades!$I$5:$I$304,Grades!$A$5:$A$304,$B12,Grades!$E$5:$E$304,F$9,Grades!$F$5:$F$304,$C$6),"")) | G12: =IF(OR($B12="",G$9=""),"",IFERROR(AVERAGEIFS(Grades!$I$5:$I$304,Grades!$A$5:$A$304,$B12,Grades!$E$5:$E$304,G$9,Grades!$F$5:$F$304,$C$6),"")) | H12: =IF(OR($B12="",H$9=""),"",IFERROR(AVERAGEIFS(Grades!$I$5:$I$304,Grades!$A$5:$A$304,$B12,Grades!$E$5:$E$304,H$9,Grades!$F$5:$F$304,$C$6),"")) | I12: =IF(OR($B12="",I$9=""),"",IFERROR(AVERAGEIFS(Grades!$I$5:$I$304,Grades!$A$5:$A$304,$B12,Grades!$E$5:$E$304,I$9,Grades!$F$5:$F$304,$C$6),"")) | J12: =IF(OR($B12="",J$9=""),"",IFERROR(AVERAGEIFS(Grades!$I$5:$I$304,Grades!$A$5:$A$304,$B12,Grades!$E$5:$E$304,J$9,Grades!$F$5:$F$304,$C$6),"")) | K12: =IF(OR($B12="",K$9=""),"",IFERROR(AVERAGEIFS(Grades!$I$5:$I$304,Grades!$A$5:$A$304,$B12,Grades!$E$5:$E$304,K$9,Grades!$F$5:$F$304,$C$6),"")) | ... O12: =IF(OR($B12="",O$9=""),"",IFERROR(AVERAGEIFS(Grades!$I$5:$I$304,Grades!$A$5:$A$304,$B12,Grades!$E$5:$E$304,O$9,Grades!$F$5:$F$304,$C$6),"")) | P12: =IF(COUNT(D12:O12)=0,"",SUM(D12:O12)) | Q12: =IF(COUNT(D12:O12)=0,"",AVERAGE(D12:O12)) | R12: =IF(Q12="","",IF(Q12>=Settings!$E$11,Settings!$F$11,IF(Q12>=Settings!$E$12,Settings!$F$12,IF(Q12>=Settings!$E$13,Settings!$F$13,IF(Q12>=Settings!$E$14,Settings!$F$14,Settings!$F$15))))) | S12: =IF(Q12="","",RANK(Q12,$Q$10:$Q$49))
A13: =IF($B13="","",4) | B13: =IFERROR(INDEX(Students!$A$5:$A$304,MATCH($C$4&"|"&$C$5&"|"&4,Students!$O$5:$O$304,0)),"") | C13: =IF($B13="","",INDEX(Students!$B$5:$B$304,MATCH($B13,Students!$A$5:$A$304,0))) | D13: =IF(OR($B13="",D$9=""),"",IFERROR(AVERAGEIFS(Grades!$I$5:$I$304,Grades!$A$5:$A$304,$B13,Grades!$E$5:$E$304,D$9,Grades!$F$5:$F$304,$C$6),"")) | E13: =IF(OR($B13="",E$9=""),"",IFERROR(AVERAGEIFS(Grades!$I$5:$I$304,Grades!$A$5:$A$304,$B13,Grades!$E$5:$E$304,E$9,Grades!$F$5:$F$304,$C$6),"")) | F13: =IF(OR($B13="",F$9=""),"",IFERROR(AVERAGEIFS(Grades!$I$5:$I$304,Grades!$A$5:$A$304,$B13,Grades!$E$5:$E$304,F$9,Grades!$F$5:$F$304,$C$6),"")) | G13: =IF(OR($B13="",G$9=""),"",IFERROR(AVERAGEIFS(Grades!$I$5:$I$304,Grades!$A$5:$A$304,$B13,Grades!$E$5:$E$304,G$9,Grades!$F$5:$F$304,$C$6),"")) | H13: =IF(OR($B13="",H$9=""),"",IFERROR(AVERAGEIFS(Grades!$I$5:$I$304,Grades!$A$5:$A$304,$B13,Grades!$E$5:$E$304,H$9,Grades!$F$5:$F$304,$C$6),"")) | I13: =IF(OR($B13="",I$9=""),"",IFERROR(AVERAGEIFS(Grades!$I$5:$I$304,Grades!$A$5:$A$304,$B13,Grades!$E$5:$E$304,I$9,Grades!$F$5:$F$304,$C$6),"")) | J13: =IF(OR($B13="",J$9=""),"",IFERROR(AVERAGEIFS(Grades!$I$5:$I$304,Grades!$A$5:$A$304,$B13,Grades!$E$5:$E$304,J$9,Grades!$F$5:$F$304,$C$6),"")) | K13: =IF(OR($B13="",K$9=""),"",IFERROR(AVERAGEIFS(Grades!$I$5:$I$304,Grades!$A$5:$A$304,$B13,Grades!$E$5:$E$304,K$9,Grades!$F$5:$F$304,$C$6),"")) | ... O13: =IF(OR($B13="",O$9=""),"",IFERROR(AVERAGEIFS(Grades!$I$5:$I$304,Grades!$A$5:$A$304,$B13,Grades!$E$5:$E$304,O$9,Grades!$F$5:$F$304,$C$6),"")) | P13: =IF(COUNT(D13:O13)=0,"",SUM(D13:O13)) | Q13: =IF(COUNT(D13:O13)=0,"",AVERAGE(D13:O13)) | R13: =IF(Q13="","",IF(Q13>=Settings!$E$11,Settings!$F$11,IF(Q13>=Settings!$E$12,Settings!$F$12,IF(Q13>=Settings!$E$13,Settings!$F$13,IF(Q13>=Settings!$E$14,Settings!$F$14,Settings!$F$15))))) | S13: =IF(Q13="","",RANK(Q13,$Q$10:$Q$49))
A14: =IF($B14="","",5) | B14: =IFERROR(INDEX(Students!$A$5:$A$304,MATCH($C$4&"|"&$C$5&"|"&5,Students!$O$5:$O$304,0)),"") | C14: =IF($B14="","",INDEX(Students!$B$5:$B$304,MATCH($B14,Students!$A$5:$A$304,0))) | D14: =IF(OR($B14="",D$9=""),"",IFERROR(AVERAGEIFS(Grades!$I$5:$I$304,Grades!$A$5:$A$304,$B14,Grades!$E$5:$E$304,D$9,Grades!$F$5:$F$304,$C$6),"")) | E14: =IF(OR($B14="",E$9=""),"",IFERROR(AVERAGEIFS(Grades!$I$5:$I$304,Grades!$A$5:$A$304,$B14,Grades!$E$5:$E$304,E$9,Grades!$F$5:$F$304,$C$6),"")) | F14: =IF(OR($B14="",F$9=""),"",IFERROR(AVERAGEIFS(Grades!$I$5:$I$304,Grades!$A$5:$A$304,$B14,Grades!$E$5:$E$304,F$9,Grades!$F$5:$F$304,$C$6),"")) | G14: =IF(OR($B14="",G$9=""),"",IFERROR(AVERAGEIFS(Grades!$I$5:$I$304,Grades!$A$5:$A$304,$B14,Grades!$E$5:$E$304,G$9,Grades!$F$5:$F$304,$C$6),"")) | H14: =IF(OR($B14="",H$9=""),"",IFERROR(AVERAGEIFS(Grades!$I$5:$I$304,Grades!$A$5:$A$304,$B14,Grades!$E$5:$E$304,H$9,Grades!$F$5:$F$304,$C$6),"")) | I14: =IF(OR($B14="",I$9=""),"",IFERROR(AVERAGEIFS(Grades!$I$5:$I$304,Grades!$A$5:$A$304,$B14,Grades!$E$5:$E$304,I$9,Grades!$F$5:$F$304,$C$6),"")) | J14: =IF(OR($B14="",J$9=""),"",IFERROR(AVERAGEIFS(Grades!$I$5:$I$304,Grades!$A$5:$A$304,$B14,Grades!$E$5:$E$304,J$9,Grades!$F$5:$F$304,$C$6),"")) | K14: =IF(OR($B14="",K$9=""),"",IFERROR(AVERAGEIFS(Grades!$I$5:$I$304,Grades!$A$5:$A$304,$B14,Grades!$E$5:$E$304,K$9,Grades!$F$5:$F$304,$C$6),"")) | ... O14: =IF(OR($B14="",O$9=""),"",IFERROR(AVERAGEIFS(Grades!$I$5:$I$304,Grades!$A$5:$A$304,$B14,Grades!$E$5:$E$304,O$9,Grades!$F$5:$F$304,$C$6),"")) | P14: =IF(COUNT(D14:O14)=0,"",SUM(D14:O14)) | Q14: =IF(COUNT(D14:O14)=0,"",AVERAGE(D14:O14)) | R14: =IF(Q14="","",IF(Q14>=Settings!$E$11,Settings!$F$11,IF(Q14>=Settings!$E$12,Settings!$F$12,IF(Q14>=Settings!$E$13,Settings!$F$13,IF(Q14>=Settings!$E$14,Settings!$F$14,Settings!$F$15))))) | S14: =IF(Q14="","",RANK(Q14,$Q$10:$Q$49))
A15: =IF($B15="","",6) | B15: =IFERROR(INDEX(Students!$A$5:$A$304,MATCH($C$4&"|"&$C$5&"|"&6,Students!$O$5:$O$304,0)),"") | C15: =IF($B15="","",INDEX(Students!$B$5:$B$304,MATCH($B15,Students!$A$5:$A$304,0))) | D15: =IF(OR($B15="",D$9=""),"",IFERROR(AVERAGEIFS(Grades!$I$5:$I$304,Grades!$A$5:$A$304,$B15,Grades!$E$5:$E$304,D$9,Grades!$F$5:$F$304,$C$6),"")) | E15: =IF(OR($B15="",E$9=""),"",IFERROR(AVERAGEIFS(Grades!$I$5:$I$304,Grades!$A$5:$A$304,$B15,Grades!$E$5:$E$304,E$9,Grades!$F$5:$F$304,$C$6),"")) | F15: =IF(OR($B15="",F$9=""),"",IFERROR(AVERAGEIFS(Grades!$I$5:$I$304,Grades!$A$5:$A$304,$B15,Grades!$E$5:$E$304,F$9,Grades!$F$5:$F$304,$C$6),"")) | G15: =IF(OR($B15="",G$9=""),"",IFERROR(AVERAGEIFS(Grades!$I$5:$I$304,Grades!$A$5:$A$304,$B15,Grades!$E$5:$E$304,G$9,Grades!$F$5:$F$304,$C$6),"")) | H15: =IF(OR($B15="",H$9=""),"",IFERROR(AVERAGEIFS(Grades!$I$5:$I$304,Grades!$A$5:$A$304,$B15,Grades!$E$5:$E$304,H$9,Grades!$F$5:$F$304,$C$6),"")) | I15: =IF(OR($B15="",I$9=""),"",IFERROR(AVERAGEIFS(Grades!$I$5:$I$304,Grades!$A$5:$A$304,$B15,Grades!$E$5:$E$304,I$9,Grades!$F$5:$F$304,$C$6),"")) | J15: =IF(OR($B15="",J$9=""),"",IFERROR(AVERAGEIFS(Grades!$I$5:$I$304,Grades!$A$5:$A$304,$B15,Grades!$E$5:$E$304,J$9,Grades!$F$5:$F$304,$C$6),"")) | K15: =IF(OR($B15="",K$9=""),"",IFERROR(AVERAGEIFS(Grades!$I$5:$I$304,Grades!$A$5:$A$304,$B15,Grades!$E$5:$E$304,K$9,Grades!$F$5:$F$304,$C$6),"")) | ... O15: =IF(OR($B15="",O$9=""),"",IFERROR(AVERAGEIFS(Grades!$I$5:$I$304,Grades!$A$5:$A$304,$B15,Grades!$E$5:$E$304,O$9,Grades!$F$5:$F$304,$C$6),"")) | P15: =IF(COUNT(D15:O15)=0,"",SUM(D15:O15)) | Q15: =IF(COUNT(D15:O15)=0,"",AVERAGE(D15:O15)) | R15: =IF(Q15="","",IF(Q15>=Settings!$E$11,Settings!$F$11,IF(Q15>=Settings!$E$12,Settings!$F$12,IF(Q15>=Settings!$E$13,Settings!$F$13,IF(Q15>=Settings!$E$14,Settings!$F$14,Settings!$F$15))))) | S15: =IF(Q15="","",RANK(Q15,$Q$10:$Q$49))
A16: =IF($B16="","",7) | B16: =IFERROR(INDEX(Students!$A$5:$A$304,MATCH($C$4&"|"&$C$5&"|"&7,Students!$O$5:$O$304,0)),"") | C16: =IF($B16="","",INDEX(Students!$B$5:$B$304,MATCH($B16,Students!$A$5:$A$304,0))) | D16: =IF(OR($B16="",D$9=""),"",IFERROR(AVERAGEIFS(Grades!$I$5:$I$304,Grades!$A$5:$A$304,$B16,Grades!$E$5:$E$304,D$9,Grades!$F$5:$F$304,$C$6),"")) | E16: =IF(OR($B16="",E$9=""),"",IFERROR(AVERAGEIFS(Grades!$I$5:$I$304,Grades!$A$5:$A$304,$B16,Grades!$E$5:$E$304,E$9,Grades!$F$5:$F$304,$C$6),"")) | F16: =IF(OR($B16="",F$9=""),"",IFERROR(AVERAGEIFS(Grades!$I$5:$I$304,Grades!$A$5:$A$304,$B16,Grades!$E$5:$E$304,F$9,Grades!$F$5:$F$304,$C$6),"")) | G16: =IF(OR($B16="",G$9=""),"",IFERROR(AVERAGEIFS(Grades!$I$5:$I$304,Grades!$A$5:$A$304,$B16,Grades!$E$5:$E$304,G$9,Grades!$F$5:$F$304,$C$6),"")) | H16: =IF(OR($B16="",H$9=""),"",IFERROR(AVERAGEIFS(Grades!$I$5:$I$304,Grades!$A$5:$A$304,$B16,Grades!$E$5:$E$304,H$9,Grades!$F$5:$F$304,$C$6),"")) | I16: =IF(OR($B16="",I$9=""),"",IFERROR(AVERAGEIFS(Grades!$I$5:$I$304,Grades!$A$5:$A$304,$B16,Grades!$E$5:$E$304,I$9,Grades!$F$5:$F$304,$C$6),"")) | J16: =IF(OR($B16="",J$9=""),"",IFERROR(AVERAGEIFS(Grades!$I$5:$I$304,Grades!$A$5:$A$304,$B16,Grades!$E$5:$E$304,J$9,Grades!$F$5:$F$304,$C$6),"")) | K16: =IF(OR($B16="",K$9=""),"",IFERROR(AVERAGEIFS(Grades!$I$5:$I$304,Grades!$A$5:$A$304,$B16,Grades!$E$5:$E$304,K$9,Grades!$F$5:$F$304,$C$6),"")) | ... O16: =IF(OR($B16="",O$9=""),"",IFERROR(AVERAGEIFS(Grades!$I$5:$I$304,Grades!$A$5:$A$304,$B16,Grades!$E$5:$E$304,O$9,Grades!$F$5:$F$304,$C$6),"")) | P16: =IF(COUNT(D16:O16)=0,"",SUM(D16:O16)) | Q16: =IF(COUNT(D16:O16)=0,"",AVERAGE(D16:O16)) | R16: =IF(Q16="","",IF(Q16>=Settings!$E$11,Settings!$F$11,IF(Q16>=Settings!$E$12,Settings!$F$12,IF(Q16>=Settings!$E$13,Settings!$F$13,IF(Q16>=Settings!$E$14,Settings!$F$14,Settings!$F$15))))) | S16: =IF(Q16="","",RANK(Q16,$Q$10:$Q$49))
A17: =IF($B17="","",8) | B17: =IFERROR(INDEX(Students!$A$5:$A$304,MATCH($C$4&"|"&$C$5&"|"&8,Students!$O$5:$O$304,0)),"") | C17: =IF($B17="","",INDEX(Students!$B$5:$B$304,MATCH($B17,Students!$A$5:$A$304,0))) | D17: =IF(OR($B17="",D$9=""),"",IFERROR(AVERAGEIFS(Grades!$I$5:$I$304,Grades!$A$5:$A$304,$B17,Grades!$E$5:$E$304,D$9,Grades!$F$5:$F$304,$C$6),"")) | E17: =IF(OR($B17="",E$9=""),"",IFERROR(AVERAGEIFS(Grades!$I$5:$I$304,Grades!$A$5:$A$304,$B17,Grades!$E$5:$E$304,E$9,Grades!$F$5:$F$304,$C$6),"")) | F17: =IF(OR($B17="",F$9=""),"",IFERROR(AVERAGEIFS(Grades!$I$5:$I$304,Grades!$A$5:$A$304,$B17,Grades!$E$5:$E$304,F$9,Grades!$F$5:$F$304,$C$6),"")) | G17: =IF(OR($B17="",G$9=""),"",IFERROR(AVERAGEIFS(Grades!$I$5:$I$304,Grades!$A$5:$A$304,$B17,Grades!$E$5:$E$304,G$9,Grades!$F$5:$F$304,$C$6),"")) | H17: =IF(OR($B17="",H$9=""),"",IFERROR(AVERAGEIFS(Grades!$I$5:$I$304,Grades!$A$5:$A$304,$B17,Grades!$E$5:$E$304,H$9,Grades!$F$5:$F$304,$C$6),"")) | I17: =IF(OR($B17="",I$9=""),"",IFERROR(AVERAGEIFS(Grades!$I$5:$I$304,Grades!$A$5:$A$304,$B17,Grades!$E$5:$E$304,I$9,Grades!$F$5:$F$304,$C$6),"")) | J17: =IF(OR($B17="",J$9=""),"",IFERROR(AVERAGEIFS(Grades!$I$5:$I$304,Grades!$A$5:$A$304,$B17,Grades!$E$5:$E$304,J$9,Grades!$F$5:$F$304,$C$6),"")) | K17: =IF(OR($B17="",K$9=""),"",IFERROR(AVERAGEIFS(Grades!$I$5:$I$304,Grades!$A$5:$A$304,$B17,Grades!$E$5:$E$304,K$9,Grades!$F$5:$F$304,$C$6),"")) | ... O17: =IF(OR($B17="",O$9=""),"",IFERROR(AVERAGEIFS(Grades!$I$5:$I$304,Grades!$A$5:$A$304,$B17,Grades!$E$5:$E$304,O$9,Grades!$F$5:$F$304,$C$6),"")) | P17: =IF(COUNT(D17:O17)=0,"",SUM(D17:O17)) | Q17: =IF(COUNT(D17:O17)=0,"",AVERAGE(D17:O17)) | R17: =IF(Q17="","",IF(Q17>=Settings!$E$11,Settings!$F$11,IF(Q17>=Settings!$E$12,Settings!$F$12,IF(Q17>=Settings!$E$13,Settings!$F$13,IF(Q17>=Settings!$E$14,Settings!$F$14,Settings!$F$15))))) | S17: =IF(Q17="","",RANK(Q17,$Q$10:$Q$49))
A18: =IF($B18="","",9) | B18: =IFERROR(INDEX(Students!$A$5:$A$304,MATCH($C$4&"|"&$C$5&"|"&9,Students!$O$5:$O$304,0)),"") | C18: =IF($B18="","",INDEX(Students!$B$5:$B$304,MATCH($B18,Students!$A$5:$A$304,0))) | D18: =IF(OR($B18="",D$9=""),"",IFERROR(AVERAGEIFS(Grades!$I$5:$I$304,Grades!$A$5:$A$304,$B18,Grades!$E$5:$E$304,D$9,Grades!$F$5:$F$304,$C$6),"")) | E18: =IF(OR($B18="",E$9=""),"",IFERROR(AVERAGEIFS(Grades!$I$5:$I$304,Grades!$A$5:$A$304,$B18,Grades!$E$5:$E$304,E$9,Grades!$F$5:$F$304,$C$6),"")) | F18: =IF(OR($B18="",F$9=""),"",IFERROR(AVERAGEIFS(Grades!$I$5:$I$304,Grades!$A$5:$A$304,$B18,Grades!$E$5:$E$304,F$9,Grades!$F$5:$F$304,$C$6),"")) | G18: =IF(OR($B18="",G$9=""),"",IFERROR(AVERAGEIFS(Grades!$I$5:$I$304,Grades!$A$5:$A$304,$B18,Grades!$E$5:$E$304,G$9,Grades!$F$5:$F$304,$C$6),"")) | H18: =IF(OR($B18="",H$9=""),"",IFERROR(AVERAGEIFS(Grades!$I$5:$I$304,Grades!$A$5:$A$304,$B18,Grades!$E$5:$E$304,H$9,Grades!$F$5:$F$304,$C$6),"")) | I18: =IF(OR($B18="",I$9=""),"",IFERROR(AVERAGEIFS(Grades!$I$5:$I$304,Grades!$A$5:$A$304,$B18,Grades!$E$5:$E$304,I$9,Grades!$F$5:$F$304,$C$6),"")) | J18: =IF(OR($B18="",J$9=""),"",IFERROR(AVERAGEIFS(Grades!$I$5:$I$304,Grades!$A$5:$A$304,$B18,Grades!$E$5:$E$304,J$9,Grades!$F$5:$F$304,$C$6),"")) | K18: =IF(OR($B18="",K$9=""),"",IFERROR(AVERAGEIFS(Grades!$I$5:$I$304,Grades!$A$5:$A$304,$B18,Grades!$E$5:$E$304,K$9,Grades!$F$5:$F$304,$C$6),"")) | ... O18: =IF(OR($B18="",O$9=""),"",IFERROR(AVERAGEIFS(Grades!$I$5:$I$304,Grades!$A$5:$A$304,$B18,Grades!$E$5:$E$304,O$9,Grades!$F$5:$F$304,$C$6),"")) | P18: =IF(COUNT(D18:O18)=0,"",SUM(D18:O18)) | Q18: =IF(COUNT(D18:O18)=0,"",AVERAGE(D18:O18)) | R18: =IF(Q18="","",IF(Q18>=Settings!$E$11,Settings!$F$11,IF(Q18>=Settings!$E$12,Settings!$F$12,IF(Q18>=Settings!$E$13,Settings!$F$13,IF(Q18>=Settings!$E$14,Settings!$F$14,Settings!$F$15))))) | S18: =IF(Q18="","",RANK(Q18,$Q$10:$Q$49))
A19: =IF($B19="","",10) | B19: =IFERROR(INDEX(Students!$A$5:$A$304,MATCH($C$4&"|"&$C$5&"|"&10,Students!$O$5:$O$304,0)),"") | C19: =IF($B19="","",INDEX(Students!$B$5:$B$304,MATCH($B19,Students!$A$5:$A$304,0))) | D19: =IF(OR($B19="",D$9=""),"",IFERROR(AVERAGEIFS(Grades!$I$5:$I$304,Grades!$A$5:$A$304,$B19,Grades!$E$5:$E$304,D$9,Grades!$F$5:$F$304,$C$6),"")) | E19: =IF(OR($B19="",E$9=""),"",IFERROR(AVERAGEIFS(Grades!$I$5:$I$304,Grades!$A$5:$A$304,$B19,Grades!$E$5:$E$304,E$9,Grades!$F$5:$F$304,$C$6),"")) | F19: =IF(OR($B19="",F$9=""),"",IFERROR(AVERAGEIFS(Grades!$I$5:$I$304,Grades!$A$5:$A$304,$B19,Grades!$E$5:$E$304,F$9,Grades!$F$5:$F$304,$C$6),"")) | G19: =IF(OR($B19="",G$9=""),"",IFERROR(AVERAGEIFS(Grades!$I$5:$I$304,Grades!$A$5:$A$304,$B19,Grades!$E$5:$E$304,G$9,Grades!$F$5:$F$304,$C$6),"")) | H19: =IF(OR($B19="",H$9=""),"",IFERROR(AVERAGEIFS(Grades!$I$5:$I$304,Grades!$A$5:$A$304,$B19,Grades!$E$5:$E$304,H$9,Grades!$F$5:$F$304,$C$6),"")) | I19: =IF(OR($B19="",I$9=""),"",IFERROR(AVERAGEIFS(Grades!$I$5:$I$304,Grades!$A$5:$A$304,$B19,Grades!$E$5:$E$304,I$9,Grades!$F$5:$F$304,$C$6),"")) | J19: =IF(OR($B19="",J$9=""),"",IFERROR(AVERAGEIFS(Grades!$I$5:$I$304,Grades!$A$5:$A$304,$B19,Grades!$E$5:$E$304,J$9,Grades!$F$5:$F$304,$C$6),"")) | K19: =IF(OR($B19="",K$9=""),"",IFERROR(AVERAGEIFS(Grades!$I$5:$I$304,Grades!$A$5:$A$304,$B19,Grades!$E$5:$E$304,K$9,Grades!$F$5:$F$304,$C$6),"")) | ... O19: =IF(OR($B19="",O$9=""),"",IFERROR(AVERAGEIFS(Grades!$I$5:$I$304,Grades!$A$5:$A$304,$B19,Grades!$E$5:$E$304,O$9,Grades!$F$5:$F$304,$C$6),"")) | P19: =IF(COUNT(D19:O19)=0,"",SUM(D19:O19)) | Q19: =IF(COUNT(D19:O19)=0,"",AVERAGE(D19:O19)) | R19: =IF(Q19="","",IF(Q19>=Settings!$E$11,Settings!$F$11,IF(Q19>=Settings!$E$12,Settings!$F$12,IF(Q19>=Settings!$E$13,Settings!$F$13,IF(Q19>=Settings!$E$14,Settings!$F$14,Settings!$F$15))))) | S19: =IF(Q19="","",RANK(Q19,$Q$10:$Q$49))
A20: =IF($B20="","",11) | B20: =IFERROR(INDEX(Students!$A$5:$A$304,MATCH($C$4&"|"&$C$5&"|"&11,Students!$O$5:$O$304,0)),"") | C20: =IF($B20="","",INDEX(Students!$B$5:$B$304,MATCH($B20,Students!$A$5:$A$304,0))) | D20: =IF(OR($B20="",D$9=""),"",IFERROR(AVERAGEIFS(Grades!$I$5:$I$304,Grades!$A$5:$A$304,$B20,Grades!$E$5:$E$304,D$9,Grades!$F$5:$F$304,$C$6),"")) | E20: =IF(OR($B20="",E$9=""),"",IFERROR(AVERAGEIFS(Grades!$I$5:$I$304,Grades!$A$5:$A$304,$B20,Grades!$E$5:$E$304,E$9,Grades!$F$5:$F$304,$C$6),"")) | F20: =IF(OR($B20="",F$9=""),"",IFERROR(AVERAGEIFS(Grades!$I$5:$I$304,Grades!$A$5:$A$304,$B20,Grades!$E$5:$E$304,F$9,Grades!$F$5:$F$304,$C$6),"")) | G20: =IF(OR($B20="",G$9=""),"",IFERROR(AVERAGEIFS(Grades!$I$5:$I$304,Grades!$A$5:$A$304,$B20,Grades!$E$5:$E$304,G$9,Grades!$F$5:$F$304,$C$6),"")) | H20: =IF(OR($B20="",H$9=""),"",IFERROR(AVERAGEIFS(Grades!$I$5:$I$304,Grades!$A$5:$A$304,$B20,Grades!$E$5:$E$304,H$9,Grades!$F$5:$F$304,$C$6),"")) | I20: =IF(OR($B20="",I$9=""),"",IFERROR(AVERAGEIFS(Grades!$I$5:$I$304,Grades!$A$5:$A$304,$B20,Grades!$E$5:$E$304,I$9,Grades!$F$5:$F$304,$C$6),"")) | J20: =IF(OR($B20="",J$9=""),"",IFERROR(AVERAGEIFS(Grades!$I$5:$I$304,Grades!$A$5:$A$304,$B20,Grades!$E$5:$E$304,J$9,Grades!$F$5:$F$304,$C$6),"")) | K20: =IF(OR($B20="",K$9=""),"",IFERROR(AVERAGEIFS(Grades!$I$5:$I$304,Grades!$A$5:$A$304,$B20,Grades!$E$5:$E$304,K$9,Grades!$F$5:$F$304,$C$6),"")) | ... O20: =IF(OR($B20="",O$9=""),"",IFERROR(AVERAGEIFS(Grades!$I$5:$I$304,Grades!$A$5:$A$304,$B20,Grades!$E$5:$E$304,O$9,Grades!$F$5:$F$304,$C$6),"")) | P20: =IF(COUNT(D20:O20)=0,"",SUM(D20:O20)) | Q20: =IF(COUNT(D20:O20)=0,"",AVERAGE(D20:O20)) | R20: =IF(Q20="","",IF(Q20>=Settings!$E$11,Settings!$F$11,IF(Q20>=Settings!$E$12,Settings!$F$12,IF(Q20>=Settings!$E$13,Settings!$F$13,IF(Q20>=Settings!$E$14,Settings!$F$14,Settings!$F$15))))) | S20: =IF(Q20="","",RANK(Q20,$Q$10:$Q$49))
A21: =IF($B21="","",12) | B21: =IFERROR(INDEX(Students!$A$5:$A$304,MATCH($C$4&"|"&$C$5&"|"&12,Students!$O$5:$O$304,0)),"") | C21: =IF($B21="","",INDEX(Students!$B$5:$B$304,MATCH($B21,Students!$A$5:$A$304,0))) | D21: =IF(OR($B21="",D$9=""),"",IFERROR(AVERAGEIFS(Grades!$I$5:$I$304,Grades!$A$5:$A$304,$B21,Grades!$E$5:$E$304,D$9,Grades!$F$5:$F$304,$C$6),"")) | E21: =IF(OR($B21="",E$9=""),"",IFERROR(AVERAGEIFS(Grades!$I$5:$I$304,Grades!$A$5:$A$304,$B21,Grades!$E$5:$E$304,E$9,Grades!$F$5:$F$304,$C$6),"")) | F21: =IF(OR($B21="",F$9=""),"",IFERROR(AVERAGEIFS(Grades!$I$5:$I$304,Grades!$A$5:$A$304,$B21,Grades!$E$5:$E$304,F$9,Grades!$F$5:$F$304,$C$6),"")) | G21: =IF(OR($B21="",G$9=""),"",IFERROR(AVERAGEIFS(Grades!$I$5:$I$304,Grades!$A$5:$A$304,$B21,Grades!$E$5:$E$304,G$9,Grades!$F$5:$F$304,$C$6),"")) | H21: =IF(OR($B21="",H$9=""),"",IFERROR(AVERAGEIFS(Grades!$I$5:$I$304,Grades!$A$5:$A$304,$B21,Grades!$E$5:$E$304,H$9,Grades!$F$5:$F$304,$C$6),"")) | I21: =IF(OR($B21="",I$9=""),"",IFERROR(AVERAGEIFS(Grades!$I$5:$I$304,Grades!$A$5:$A$304,$B21,Grades!$E$5:$E$304,I$9,Grades!$F$5:$F$304,$C$6),"")) | J21: =IF(OR($B21="",J$9=""),"",IFERROR(AVERAGEIFS(Grades!$I$5:$I$304,Grades!$A$5:$A$304,$B21,Grades!$E$5:$E$304,J$9,Grades!$F$5:$F$304,$C$6),"")) | K21: =IF(OR($B21="",K$9=""),"",IFERROR(AVERAGEIFS(Grades!$I$5:$I$304,Grades!$A$5:$A$304,$B21,Grades!$E$5:$E$304,K$9,Grades!$F$5:$F$304,$C$6),"")) | ... O21: =IF(OR($B21="",O$9=""),"",IFERROR(AVERAGEIFS(Grades!$I$5:$I$304,Grades!$A$5:$A$304,$B21,Grades!$E$5:$E$304,O$9,Grades!$F$5:$F$304,$C$6),"")) | P21: =IF(COUNT(D21:O21)=0,"",SUM(D21:O21)) | Q21: =IF(COUNT(D21:O21)=0,"",AVERAGE(D21:O21)) | R21: =IF(Q21="","",IF(Q21>=Settings!$E$11,Settings!$F$11,IF(Q21>=Settings!$E$12,Settings!$F$12,IF(Q21>=Settings!$E$13,Settings!$F$13,IF(Q21>=Settings!$E$14,Settings!$F$14,Settings!$F$15))))) | S21: =IF(Q21="","",RANK(Q21,$Q$10:$Q$49))
A22: =IF($B22="","",13) | B22: =IFERROR(INDEX(Students!$A$5:$A$304,MATCH($C$4&"|"&$C$5&"|"&13,Students!$O$5:$O$304,0)),"") | C22: =IF($B22="","",INDEX(Students!$B$5:$B$304,MATCH($B22,Students!$A$5:$A$304,0))) | D22: =IF(OR($B22="",D$9=""),"",IFERROR(AVERAGEIFS(Grades!$I$5:$I$304,Grades!$A$5:$A$304,$B22,Grades!$E$5:$E$304,D$9,Grades!$F$5:$F$304,$C$6),"")) | E22: =IF(OR($B22="",E$9=""),"",IFERROR(AVERAGEIFS(Grades!$I$5:$I$304,Grades!$A$5:$A$304,$B22,Grades!$E$5:$E$304,E$9,Grades!$F$5:$F$304,$C$6),"")) | F22: =IF(OR($B22="",F$9=""),"",IFERROR(AVERAGEIFS(Grades!$I$5:$I$304,Grades!$A$5:$A$304,$B22,Grades!$E$5:$E$304,F$9,Grades!$F$5:$F$304,$C$6),"")) | G22: =IF(OR($B22="",G$9=""),"",IFERROR(AVERAGEIFS(Grades!$I$5:$I$304,Grades!$A$5:$A$304,$B22,Grades!$E$5:$E$304,G$9,Grades!$F$5:$F$304,$C$6),"")) | H22: =IF(OR($B22="",H$9=""),"",IFERROR(AVERAGEIFS(Grades!$I$5:$I$304,Grades!$A$5:$A$304,$B22,Grades!$E$5:$E$304,H$9,Grades!$F$5:$F$304,$C$6),"")) | I22: =IF(OR($B22="",I$9=""),"",IFERROR(AVERAGEIFS(Grades!$I$5:$I$304,Grades!$A$5:$A$304,$B22,Grades!$E$5:$E$304,I$9,Grades!$F$5:$F$304,$C$6),"")) | J22: =IF(OR($B22="",J$9=""),"",IFERROR(AVERAGEIFS(Grades!$I$5:$I$304,Grades!$A$5:$A$304,$B22,Grades!$E$5:$E$304,J$9,Grades!$F$5:$F$304,$C$6),"")) | K22: =IF(OR($B22="",K$9=""),"",IFERROR(AVERAGEIFS(Grades!$I$5:$I$304,Grades!$A$5:$A$304,$B22,Grades!$E$5:$E$304,K$9,Grades!$F$5:$F$304,$C$6),"")) | ... O22: =IF(OR($B22="",O$9=""),"",IFERROR(AVERAGEIFS(Grades!$I$5:$I$304,Grades!$A$5:$A$304,$B22,Grades!$E$5:$E$304,O$9,Grades!$F$5:$F$304,$C$6),"")) | P22: =IF(COUNT(D22:O22)=0,"",SUM(D22:O22)) | Q22: =IF(COUNT(D22:O22)=0,"",AVERAGE(D22:O22)) | R22: =IF(Q22="","",IF(Q22>=Settings!$E$11,Settings!$F$11,IF(Q22>=Settings!$E$12,Settings!$F$12,IF(Q22>=Settings!$E$13,Settings!$F$13,IF(Q22>=Settings!$E$14,Settings!$F$14,Settings!$F$15))))) | S22: =IF(Q22="","",RANK(Q22,$Q$10:$Q$49))
A23: =IF($B23="","",14) | B23: =IFERROR(INDEX(Students!$A$5:$A$304,MATCH($C$4&"|"&$C$5&"|"&14,Students!$O$5:$O$304,0)),"") | C23: =IF($B23="","",INDEX(Students!$B$5:$B$304,MATCH($B23,Students!$A$5:$A$304,0))) | D23: =IF(OR($B23="",D$9=""),"",IFERROR(AVERAGEIFS(Grades!$I$5:$I$304,Grades!$A$5:$A$304,$B23,Grades!$E$5:$E$304,D$9,Grades!$F$5:$F$304,$C$6),"")) | E23: =IF(OR($B23="",E$9=""),"",IFERROR(AVERAGEIFS(Grades!$I$5:$I$304,Grades!$A$5:$A$304,$B23,Grades!$E$5:$E$304,E$9,Grades!$F$5:$F$304,$C$6),"")) | F23: =IF(OR($B23="",F$9=""),"",IFERROR(AVERAGEIFS(Grades!$I$5:$I$304,Grades!$A$5:$A$304,$B23,Grades!$E$5:$E$304,F$9,Grades!$F$5:$F$304,$C$6),"")) | G23: =IF(OR($B23="",G$9=""),"",IFERROR(AVERAGEIFS(Grades!$I$5:$I$304,Grades!$A$5:$A$304,$B23,Grades!$E$5:$E$304,G$9,Grades!$F$5:$F$304,$C$6),"")) | H23: =IF(OR($B23="",H$9=""),"",IFERROR(AVERAGEIFS(Grades!$I$5:$I$304,Grades!$A$5:$A$304,$B23,Grades!$E$5:$E$304,H$9,Grades!$F$5:$F$304,$C$6),"")) | I23: =IF(OR($B23="",I$9=""),"",IFERROR(AVERAGEIFS(Grades!$I$5:$I$304,Grades!$A$5:$A$304,$B23,Grades!$E$5:$E$304,I$9,Grades!$F$5:$F$304,$C$6),"")) | J23: =IF(OR($B23="",J$9=""),"",IFERROR(AVERAGEIFS(Grades!$I$5:$I$304,Grades!$A$5:$A$304,$B23,Grades!$E$5:$E$304,J$9,Grades!$F$5:$F$304,$C$6),"")) | K23: =IF(OR($B23="",K$9=""),"",IFERROR(AVERAGEIFS(Grades!$I$5:$I$304,Grades!$A$5:$A$304,$B23,Grades!$E$5:$E$304,K$9,Grades!$F$5:$F$304,$C$6),"")) | ... O23: =IF(OR($B23="",O$9=""),"",IFERROR(AVERAGEIFS(Grades!$I$5:$I$304,Grades!$A$5:$A$304,$B23,Grades!$E$5:$E$304,O$9,Grades!$F$5:$F$304,$C$6),"")) | P23: =IF(COUNT(D23:O23)=0,"",SUM(D23:O23)) | Q23: =IF(COUNT(D23:O23)=0,"",AVERAGE(D23:O23)) | R23: =IF(Q23="","",IF(Q23>=Settings!$E$11,Settings!$F$11,IF(Q23>=Settings!$E$12,Settings!$F$12,IF(Q23>=Settings!$E$13,Settings!$F$13,IF(Q23>=Settings!$E$14,Settings!$F$14,Settings!$F$15))))) | S23: =IF(Q23="","",RANK(Q23,$Q$10:$Q$49))
